<mujoco model="physlab_franka_pick">
  <compiler angle="radian"/>
  <option timestep="0.01" integrator="RK4" gravity="0 0 -9.81"/>
  <default>
    <joint damping="0.08" armature="0.01"/>
    <geom friction="0.8 0.1 0.1"/>
  </default>
  <worldbody>
    <light pos="0 0 2"/>
    <geom name="table" type="box" pos="0.55 0 0.35" size="0.45 0.45 0.03"/>
    <body name="panda_link0" pos="0 0 0.40">
      <joint name="panda_joint1" type="hinge" axis="0 0 1" range="-2.9 2.9" limited="true"/>
      <geom type="capsule" fromto="0 0 0 0 0 0.12" size="0.035" mass="0.7"/>
      <body name="panda_link1" pos="0 0 0.12">
        <joint name="panda_joint2" type="hinge" axis="0 1 0" range="-1.8 1.8" limited="true"/>
        <geom type="capsule" fromto="0 0 0 0.12 0 0.08" size="0.03" mass="0.6"/>
        <body name="panda_link2" pos="0.12 0 0.08">
          <joint name="panda_joint3" type="hinge" axis="0 1 0" range="-2.8 2.8" limited="true"/>
          <geom type="capsule" fromto="0 0 0 0.12 0 -0.02" size="0.028" mass="0.5"/>
          <body name="panda_link3" pos="0.12 0 -0.02">
            <joint name="panda_joint4" type="hinge" axis="1 0 0" range="-2.9 0.0" limited="true"/>
            <geom type="capsule" fromto="0 0 0 0.10 0 0.04" size="0.026" mass="0.4"/>
            <body name="panda_link4" pos="0.10 0 0.04">
              <joint name="panda_joint5" type="hinge" axis="0 1 0" range="-2.9 2.9" limited="true"/>
              <geom type="capsule" fromto="0 0 0 0.09 0 0.02" size="0.024" mass="0.3"/>
              <body name="panda_link5" pos="0.09 0 0.02">
                <joint name="panda_joint6" type="hinge" axis="1 0 0" range="-0.1 3.7" limited="true"/>
                <geom type="capsule" fromto="0 0 0 0.08 0 0" size="0.022" mass="0.2"/>
                <body name="panda_hand" pos="0.08 0 0">
                  <joint name="panda_joint7" type="hinge" axis="0 1 0" range="-2.9 2.9" limited="true"/>
                  <geom type="sphere" size="0.04" mass="0.2"/>
                  <site name="gripper_site" pos="0.06 0 0" size="0.02"/>
                </body>
              </body>
            </body>
          </body>
        </body>
      </body>
    </body>
    <body name="cube" pos="0.55 0 0.42">
      <freejoint name="cube_free"/>
      <geom name="cube_geom" type="box" size="0.025 0.025 0.025" mass="0.05" rgba="0.2 0.7 0.9 1"/>
    </body>
    <body name="target_mocap" mocap="true" pos="0.65 0.10 0.42">
      <site name="target_site" type="sphere" size="0.035" rgba="0.2 1 0.2 0.5"/>
    </body>
  </worldbody>
  <actuator>
    <motor name="act1" joint="panda_joint1" ctrllimited="true" ctrlrange="-1 1" gear="12"/>
    <motor name="act2" joint="panda_joint2" ctrllimited="true" ctrlrange="-1 1" gear="12"/>
    <motor name="act3" joint="panda_joint3" ctrllimited="true" ctrlrange="-1 1" gear="12"/>
    <motor name="act4" joint="panda_joint4" ctrllimited="true" ctrlrange="-1 1" gear="12"/>
    <motor name="act5" joint="panda_joint5" ctrllimited="true" ctrlrange="-1 1" gear="12"/>
    <motor name="act6" joint="panda_joint6" ctrllimited="true" ctrlrange="-1 1" gear="12"/>
    <motor name="act7" joint="panda_joint7" ctrllimited="true" ctrlrange="-1 1" gear="12"/>
  </actuator>
</mujoco>
